Workbook

Sheet Inventaario
A1: Kategoria | B1: Tuote | C1: Merkki | D1: Pakkauskoko (g) | E1: Pakkauksia | F1: Tila | G1: Jäljellä (g) | H1: Parasta ennen | I1: Huomiot
A2: Pastat ja nuudelit | B2: Lasagnelevyt | C2: Coop | D2: 500 | E2: 1 | F2: Avaamaton | G2: 500 | I2: Durumvehnä + kananmuna
A3: Pastat ja nuudelit | B3: Pikamakaroni | C3: Coop Xtra | D3: 1000 | E3: 1 | F3: Avattu | G3: 600
A4: Pastat ja nuudelit | B4: Fusilli No. 48 | C4: Rummo | D4: 500 | E4: 1 | F4: Avattu | G4: 200
A5: Pastat ja nuudelit | B5: Täysjyvä rakettispagetti | C5: Myllyn Paras | D5: 350 | E5: 1 | F5: Avattu | G5: 115
A6: Pastat ja nuudelit | B6: Tumma makaroni | C6: Myllyn Paras | D6: 400 | E6: 1 | F6: Avattu | G6: 130
A7: Pastat ja nuudelit | B7: Eggnoodles | C7: Coop Taste of Asia | D7: 250 | E7: 1 | F7: Avattu | G7: 140
A8: Pastat ja nuudelit | B8: Riisinuudelit | D8: 200 | E8: 1 | F8: Avattu | G8: 110
A9: Pastat ja nuudelit | B9: Bánh Phở -riisinuudeli | C9: Chantaboon | D9: 400 | E9: 1 | F9: Avattu | G9: 220 | I9: Tuotettu Thaimaassa
A10: Pastat ja nuudelit | B10: Vehnä-instantnuudelipalat | E10: 3 | F10: Avattu | G10: 255 | I10: 3 palaa jäljellä, alkuperäinen pakkaus ei tallessa, paino arvio (~85 g/pala)
A11: Pastat ja nuudelit | B11: Yakisoba Veggie -instantnuudeli | D11: 85 | E11: 1 | F11: Avattu | G11: 85 | I11: 1 annospakkaus, paino arvio
A12: Riisit | B12: Sushiriisi | C12: Fukishi | D12: 500 | E12: 1 | F12: Avaamaton | G12: 500
A13: Riisit | B13: Pitkäjyväinen riisi (Parboiled) | D13: 1000 | E13: 1 | F13: Avattu | G13: 750
A14: Riisit | B14: Puuroriisi (Grötris) | C14: Coop | D14: 1000 | E14: 1 | F14: Avattu | G14: 330
A15: Riisit | B15: Puuroriisi | C15: Risella | D15: 1000 | E15: 1 | F15: Avattu | G15: 330
A16: Riisit | B16: Jasmiiniriisi | C16: Preah Vihear | D16: 10000 | E16: 1 | F16: Avaamaton | G16: 10000 | I16: Cambodia, SRP-sertifioitu
A17: Jyvät ja muut viljat | B17: Ohrasuurimo, kokonainen | C17: Korpelan Mylly | D17: 600 | E17: 1 | F17: Avaamaton | G17: 600
A18: Jyvät ja muut viljat | B18: Ohrasuurimo, kokonainen | C18: Korpelan Mylly | D18: 600 | E18: 1 | F18: Avattu | G18: 300
A19: Jyvät ja muut viljat | B19: Kvinoa | C19: Risella | D19: 500 | E19: 1 | F19: Avattu | G19: 250
A20: Jyvät ja muut viljat | B20: Villikaura (gluteeniton) | C20: Myllärin | D20: 950 | E20: 1 | F20: Avattu | G20: 240
A21: Jyvät ja muut viljat | B21: Couscous | C21: Coop | D21: 500 | E21: 1 | F21: Avattu | G21: 250
A22: Jyvät ja muut viljat | B22: Hedelmämysli | C22: Kotimaista | D22: 1000 | E22: 1 | F22: Avattu | G22: 900
A23: Jyvät ja muut viljat | B23: Mannasuurimo | C23: Kotimaista | D23: 1000 | E23: 1 | F23: Avattu | G23: 900
A24: Jyvät ja muut viljat | B24: Kaurahiutale | C24: Kotimaista | D24: 1000 | E24: 1 | F24: Avattu | G24: 200
A25: Jyvät ja muut viljat | B25: 4 viljan hiutale | C25: Kotimaista | D25: 1000 | E25: 1 | F25: Avattu | G25: 900
A26: Palkokasvit | B26: Punaiset linssit (säilyke) | C26: Coop | D26: 380 | E26: 1 | F26: Avaamaton | G26: 380 | I26: Tölkki; valutettu paino 230 g
A27: Palkokasvit | B27: Vihreät linssit (kuivat) | D27: 400 | E27: 1 | F27: Avaamaton | G27: 400
A28: Palkokasvit | B28: Vihreä linssi, luomu (kuivat) | C28: Foodin | D28: 500 | E28: 1 | F28: Avattu | G28: 165
A29: Palkokasvit | B29: Borlottipavut (säilyke, luomu) | C29: Coop EKO | D29: 380 | E29: 1 | F29: Avaamaton | G29: 380 | I29: Tölkki; valutettu paino 230 g
A30: Palkokasvit | B30: Kikherneet (säilyke) | C30: Coop Xtra | D30: 380 | E30: 1 | F30: Avaamaton | G30: 380 | I30: Tölkki; valutettu paino 230 g
A31: Palkokasvit | B31: Mungpavut (kuivat) | C31: Go Green | D31: 500 | E31: 1 | F31: Avattu | G31: 250 | H31: 45672 | I31: Päiväys ohi yli vuoden; tarkista haju/hyönteiset
A32: Palkokasvit | B32: Keltaiset linssit | C32: Go Green Svenska | D32: 400 | E32: 1 | F32: Avattu | G32: 80 | H32: 45547 | I32: Päiväys ohi n. 1,5 v; tarkista haju/hyönteiset
A33: Jauhot | B33: Vehnäjauho | C33: Coop Xtra | D33: 2000 | E33: 1 | F33: Avaamaton | G33: 2000
A34: Jauhot | B34: Kikhernejauho, luomu | C34: Foodin | D34: 350 | E34: 1 | F34: Avattu | G34: 175
A35: Säilyketomaatit | B35: Tomaattimurska, maustamaton | C35: Coop | D35: 390 | E35: 2 | F35: Avaamaton | G35: 780 | I35: 2 pakkausta
A36: Säilyketomaatit | B36: Tomaattimurska, maustamaton (luomu) | C36: Coop EKO | D36: 390 | E36: 1 | F36: Avaamaton | G36: 390
A37: Aasialaiset / umami | B37: Sushi nori, paahdettu | C37: Asian Food Service | D37: 125 | E37: 1 | F37: Avattu | G37: 70 | I37: 50 levyä alkuperäisessä
A38: Aasialaiset / umami | B38: Shiitake-sienet, kuivatut | D38: 100 | E38: 1 | F38: Avattu | G38: 55
A39: Aasialaiset / umami | B39: Katsuobushi (bonitohiutaleet) | C39: Daewang | D39: 50 | E39: 1 | F39: Avattu | G39: 25 | I39: Dashi-liemen ainekset
A40: Aasialaiset / umami | B40: Kombu (merilevätikku) | E40: 1 | F40: Avattu | I40: 6 tikkua jäljellä; pakkauskoko ei tiedossa; dashi-liemen ainekset
...

Sheet Pakastin
A1: Kategoria | B1: Tuote | C1: Merkki | D1: Määrä | E1: Yksikkö | F1: Pakastettu pvm | G1: Parasta ennen | H1: Huomiot
A2: Sienet | B2: Kantarelli | D2: 1200 | E2: g | H2: Useita pakastepusseja
A3: Sienet | B3: Korvasieni | D3: 840 | E3: g | H3: Esikäsittele huolellisesti ennen käyttöä (kaksi keittoa, vesi pois)
A4: Marjat ja hedelmät | B4: Punaherukka | D4: 3000 | E4: g
A5: Marjat ja hedelmät | B5: Omenasiivut | D5: 320 | E5: g
A6: Pakastevihannekset | B6: Ohuet vihreät pavut (haricots verts) | D6: 311 | E6: g | H6: Alkuperäinen pakkaus 500 g
A7: Pakastevihannekset | B7: Makea maissi | D7: 450 | E7: g | H7: Avaamaton
A8: Pakastevihannekset | B8: Peruna-sipuli sekoitus | C8: Kotimaista | D8: 200 | E8: g | H8: Alkuperäinen pakkaus 1 kg
A9: Pakastevihannekset | B9: Hakattu pinaatti | D9: 850 | E9: g | H9: Alkuperäinen pakkaus 1 kg
A10: Pakastevihannekset | B10: Vihannessekoitus | C10: Kotimaista | D10: 135 | E10: g | H10: Alkuperäinen pakkaus 250 g
A11: Pakastevihannekset | B11: Bataattikuutiot | D11: 1154 | E11: g
A12: Pakastevihannekset | B12: Keittojuurekset (peruna, lanttu, porkkana, palsternakka, purjo) | C12: Coop | D12: 750 | E12: g | H12: Avaamaton
A13: Pakastevihannekset | B13: Parsakaali | D13: 500 | E13: g | H13: Avaamaton
A14: Pakastevihannekset | B14: Kesäkurpitsa, raastettu | D14: 1900 | E14: g
A15: Pakastevihannekset | B15: Kesäkurpitsa, kuutioitu | D15: 1600 | E15: g
A16: Leivonta | B16: Piirakkataikina, pyöreä | C16: Myllyn Paras | D16: 380 | E16: g | H16: Avaamaton; laktoositon
A17: Leivonta | B17: Pizzapohjat (4 kpl) | C17: Kotimaista | D17: 360 | E17: g | H17: Avaamaton
A18: Liha | B18: Poron kuivaliha | D18: 679 | E18: g | H18: 2 erää
A19: Kala | B19: Lohifilee | D19: 1030 | E19: g

Sheet Yhteenveto
A1: Yhteenveto
A3: Kuiva-aineet (Inventaario)
A4: Kategoria | B4: Nimikkeitä | C4: Jäljellä yhteensä (g)
A5: Pastat ja nuudelit | B5: =COUNTIF(Inventaario!A:A,"Pastat ja nuudelit") -> 10 | C5: =SUMIFS(Inventaario!G:G,Inventaario!A:A,"Pastat ja nuudelit") -> 2355
A6: Riisit | B6: =COUNTIF(Inventaario!A:A,"Riisit") -> 5 | C6: =SUMIFS(Inventaario!G:G,Inventaario!A:A,"Riisit") -> 11910
A7: Jyvät ja muut viljat | B7: =COUNTIF(Inventaario!A:A,"Jyvät ja muut viljat") -> 9 | C7: =SUMIFS(Inventaario!G:G,Inventaario!A:A,"Jyvät ja muut viljat") -> 4540
A8: Palkokasvit | B8: =COUNTIF(Inventaario!A:A,"Palkokasvit") -> 7 | C8: =SUMIFS(Inventaario!G:G,Inventaario!A:A,"Palkokasvit") -> 2035
A9: Jauhot | B9: =COUNTIF(Inventaario!A:A,"Jauhot") -> 2 | C9: =SUMIFS(Inventaario!G:G,Inventaario!A:A,"Jauhot") -> 2175
A10: Säilyketomaatit | B10: =COUNTIF(Inventaario!A:A,"Säilyketomaatit") -> 2 | C10: =SUMIFS(Inventaario!G:G,Inventaario!A:A,"Säilyketomaatit") -> 1170
A11: Aasialaiset / umami | B11: =COUNTIF(Inventaario!A:A,"Aasialaiset / umami") -> 4 | C11: =SUMIFS(Inventaario!G:G,Inventaario!A:A,"Aasialaiset / umami") -> 150
A12: Siemenet | B12: =COUNTIF(Inventaario!A:A,"Siemenet") -> 2 | C12: =SUMIFS(Inventaario!G:G,Inventaario!A:A,"Siemenet") -> 1200
A13: Muut | B13: =COUNTIF(Inventaario!A:A,"Muut") -> 7 | C13: =SUMIFS(Inventaario!G:G,Inventaario!A:A,"Muut") -> 2022
A14: Yhteensä kuivat | B14: =SUM(B5:B13) -> 48 | C14: =SUM(C5:C13) -> 27557
A17: Pakastin
A18: Kategoria | B18: Nimikkeitä | C18: Määrä yhteensä (yks. vaihtelee)
A19: Sienet | B19: =COUNTIF(Pakastin!A:A,"Sienet") -> 2 | C19: =SUMIFS(Pakastin!D:D,Pakastin!A:A,"Sienet") -> 2040
A20: Marjat ja hedelmät | B20: =COUNTIF(Pakastin!A:A,"Marjat ja hedelmät") -> 2 | C20: =SUMIFS(Pakastin!D:D,Pakastin!A:A,"Marjat ja hedelmät") -> 3320
A21: Pakastevihannekset | B21: =COUNTIF(Pakastin!A:A,"Pakastevihannekset") -> 10 | C21: =SUMIFS(Pakastin!D:D,Pakastin!A:A,"Pakastevihannekset") -> 7850
A22: Leivonta | B22: =COUNTIF(Pakastin!A:A,"Leivonta") -> 2 | C22: =SUMIFS(Pakastin!D:D,Pakastin!A:A,"Leivonta") -> 740
A23: Liha | B23: =COUNTIF(Pakastin!A:A,"Liha") -> 1 | C23: =SUMIFS(Pakastin!D:D,Pakastin!A:A,"Liha") -> 679
A24: Kala | B24: =COUNTIF(Pakastin!A:A,"Kala") -> 1 | C24: =SUMIFS(Pakastin!D:D,Pakastin!A:A,"Kala") -> 1030
A25: Yhteensä pakastin | B25: =SUM(B19:B24) -> 18
